werkzeug.routing.exceptions.BuildError
werkzeug.routing.exceptions.BuildError: Could not build url for endpoint 'groups.my_groups'. Did you mean 'modern_groups.manage_group' instead?

Traceback (most recent call last)
File "E:\anaconda\Lib\site-packages\flask\app.py", line 917, in full_dispatch_request
rv = self.dispatch_request()
     ^^^^^^^^^^^^^^^^^^^^^^^
File "E:\anaconda\Lib\site-packages\flask\app.py", line 902, in dispatch_request
return self.ensure_sync(self.view_functions[rule.endpoint])(**view_args)  # type: ignore[no-any-return]
       ^^^^^^^^^^^^^^^^^^^^^^^^^^^^^^^^^^^^^^^^^^^^^^^^^^^^^^^^^^^^^^^^^
File "c:\Users\Hemanth\OneDrive\Desktop\projects\PBL Project\RailServe\main.py", line 46, in index
return render_template('index.html', trains=running_trains, stations=stations)
       ^^^^^^^^^^^^^^^^^^^^^^^^^^^^^^^^^^^^^^^^^^^^^^^^^^^^^^^^^^^^^^^^^^^^^^^
File "E:\anaconda\Lib\site-packages\flask\templating.py", line 150, in render_template
return _render(app, template, context)
       ^^^^^^^^^^^^^^^^^^^^^^^^^^^^^^^
File "E:\anaconda\Lib\site-packages\flask\templating.py", line 131, in _render
rv = template.render(context)
     ^^^^^^^^^^^^^^^^^^^^^^^^
File "E:\anaconda\Lib\site-packages\jinja2\environment.py", line 1295, in render
self.environment.handle_exception()
^^^^^^^^^^^^^^^^^^^^^^^^^^^^^^^^^^^
File "E:\anaconda\Lib\site-packages\jinja2\environment.py", line 942, in handle_exception
raise rewrite_traceback_stack(source=source)
^^^^^^^^^^^^^^^^^^^^^^^^^^^^^^^^^^^^^^^^^^^^
File "c:\Users\Hemanth\OneDrive\Desktop\projects\PBL Project\RailServe\templates\index.html", line 1, in top-level template code
{% extends "base.html" %}
File "c:\Users\Hemanth\OneDrive\Desktop\projects\PBL Project\RailServe\templates\base.html", line 2328, in top-level template code
<a href="{{ url_for('groups.my_groups') }}" class="dropdown-item">
File "E:\anaconda\Lib\site-packages\flask\app.py", line 1121, in url_for
return self.handle_url_build_error(error, endpoint, values)
       ^^^^^^^^^^^^^^^^^^^^^^^^^^^^^^^^^^^^^^^^^^^^^^^^^^^^
File "E:\anaconda\Lib\site-packages\flask\app.py", line 1110, in url_for
rv = url_adapter.build(  # type: ignore[union-attr]
     
File "E:\anaconda\Lib\site-packages\werkzeug\routing\map.py", line 924, in build
raise BuildError(endpoint, values, method, self)
^^^^^^^^^^^^^^^^^^^^^^^^^^^^^^^^^^^^^^^^^^^^^^^^
During handling of the above exception, another exception occurred:
File "E:\anaconda\Lib\site-packages\flask\app.py", line 1536, in __call__
return self.wsgi_app(environ, start_response)
       ^^^^^^^^^^^^^^^^^^^^^^^^^^^^^^^^^^^^^^
File "E:\anaconda\Lib\site-packages\werkzeug\middleware\proxy_fix.py", line 183, in __call__
return self.app(environ, start_response)
       ^^^^^^^^^^^^^^^^^^^^^^^^^^^^^^^^^
File "E:\anaconda\Lib\site-packages\flask\app.py", line 1514, in wsgi_app
response = self.handle_exception(e)
           ^^^^^^^^^^^^^^^^^^^^^^^^
File "E:\anaconda\Lib\site-packages\flask\app.py", line 1511, in wsgi_app
response = self.full_dispatch_request()
           ^^^^^^^^^^^^^^^^^^^^^^^^^^^^
File "E:\anaconda\Lib\site-packages\flask\app.py", line 919, in full_dispatch_request
rv = self.handle_user_exception(e)
     ^^^^^^^^^^^^^^^^^^^^^^^^^^^^^
File "E:\anaconda\Lib\site-packages\flask\app.py", line 809, in handle_user_exception
return self.ensure_sync(handler)(e)  # type: ignore[no-any-return]
       ^^^^^^^^^^^^^^^^^^^^^^^^^^^^
File "c:\Users\Hemanth\OneDrive\Desktop\projects\PBL Project\RailServe\src\app.py", line 140, in handle_exception
return render_template('errors/500.html', error_message=error_message), 500
       ^^^^^^^^^^^^^^^^^^^^^^^^^^^^^^^^^^^^^^^^^^^^^^^^^^^^^^^^^^^^^^^
File "E:\anaconda\Lib\site-packages\flask\templating.py", line 150, in render_template
return _render(app, template, context)
       ^^^^^^^^^^^^^^^^^^^^^^^^^^^^^^^
File "E:\anaconda\Lib\site-packages\flask\templating.py", line 131, in _render
rv = template.render(context)
     ^^^^^^^^^^^^^^^^^^^^^^^^
File "E:\anaconda\Lib\site-packages\jinja2\environment.py", line 1295, in render
self.environment.handle_exception()
^^^^^^^^^^^^^^^^^^^^^^^^^^^^^^^^^^^
File "E:\anaconda\Lib\site-packages\jinja2\environment.py", line 942, in handle_exception
raise rewrite_traceback_stack(source=source)
^^^^^^^^^^^^^^^^^^^^^^^^^^^^^^^^^^^^^^^^^^^^
File "c:\Users\Hemanth\OneDrive\Desktop\projects\PBL Project\RailServe\templates\errors\500.html", line 1, in top-level template code
{% extends "base.html" %}
File "c:\Users\Hemanth\OneDrive\Desktop\projects\PBL Project\RailServe\templates\base.html", line 2328, in top-level template code
<a href="{{ url_for('groups.my_groups') }}" class="dropdown-item">
File "E:\anaconda\Lib\site-packages\flask\app.py", line 1121, in url_for
return self.handle_url_build_error(error, endpoint, values)
       ^^^^^^^^^^^^^^^^^^^^^^^^^^^^^^^^^^^^^^^^^^^^^^^^^^^^
File "E:\anaconda\Lib\site-packages\flask\app.py", line 1110, in url_for
rv = url_adapter.build(  # type: ignore[union-attr]
     
File "E:\anaconda\Lib\site-packages\werkzeug\routing\map.py", line 924, in build
raise BuildError(endpoint, values, method, self)
^^^^^^^^^^^^^^^^^^^^^^^^^^^^^^^^^^^^^^^^^^^^^^^^
werkzeug.routing.exceptions.BuildError: Could not build url for endpoint 'groups.my_groups'. Did you mean 'modern_groups.manage_group' instead?
The debugger caught an exception in your WSGI application. You can now look at the traceback which led to the error.
To switch between the interactive traceback and the plaintext one, you can click on the "Traceback" headline. From the text traceback you can also create a paste of it. For code execution mouse-over the frame you want to debug and click on the console icon on the right side.

You can execute arbitrary Python code in the stack frames and there are some extra helpers available for introspection:

dump() shows all variables in the frame
dump(obj) dumps all that's known about the object
